[2023-01-21T04:11:28.976+0000] {taskinstance.py:1165} INFO - Dependencies all met for <TaskInstance: real_estate_data_pipeline.read_csv scheduled__2022-01-10T11:00:00+00:00 [queued]>
[2023-01-21T04:11:28.987+0000] {taskinstance.py:1165} INFO - Dependencies all met for <TaskInstance: real_estate_data_pipeline.read_csv scheduled__2022-01-10T11:00:00+00:00 [queued]>
[2023-01-21T04:11:28.988+0000] {taskinstance.py:1362} INFO - 
--------------------------------------------------------------------------------
[2023-01-21T04:11:28.989+0000] {taskinstance.py:1363} INFO - Starting attempt 2 of 2
[2023-01-21T04:11:28.989+0000] {taskinstance.py:1364} INFO - 
--------------------------------------------------------------------------------
[2023-01-21T04:11:29.011+0000] {taskinstance.py:1383} INFO - Executing <Task(PythonOperator): read_csv> on 2022-01-10 11:00:00+00:00
[2023-01-21T04:11:29.018+0000] {standard_task_runner.py:54} INFO - Started process 5442 to run task
[2023-01-21T04:11:29.043+0000] {standard_task_runner.py:82} INFO - Running: ['***', 'tasks', 'run', 'real_estate_data_pipeline', 'read_csv', 'scheduled__2022-01-10T11:00:00+00:00', '--job-id', '488', '--raw', '--subdir', 'DAGS_FOLDER/real_estate_dag.py', '--cfg-path', '/tmp/tmp7zewkvgi']
[2023-01-21T04:11:29.049+0000] {standard_task_runner.py:83} INFO - Job 488: Subtask read_csv
[2023-01-21T04:11:29.059+0000] {dagbag.py:525} INFO - Filling up the DagBag from /opt/***/dags/real_estate_dag.py
[2023-01-21T04:11:29.912+0000] {task_command.py:384} INFO - Running <TaskInstance: real_estate_data_pipeline.read_csv scheduled__2022-01-10T11:00:00+00:00 [running]> on host 2fb4a96081a8
[2023-01-21T04:11:30.039+0000] {taskinstance.py:1592} INFO - Exporting the following env vars:
AIRFLOW_CTX_DAG_OWNER=me
AIRFLOW_CTX_DAG_ID=real_estate_data_pipeline
AIRFLOW_CTX_TASK_ID=read_csv
AIRFLOW_CTX_EXECUTION_DATE=2022-01-10T11:00:00+00:00
AIRFLOW_CTX_TRY_NUMBER=2
AIRFLOW_CTX_DAG_RUN_ID=scheduled__2022-01-10T11:00:00+00:00
[2023-01-21T04:11:30.046+0000] {taskinstance.py:1851} ERROR - Task failed with exception
Traceback (most recent call last):
  File "/home/airflow/.local/lib/python3.7/site-packages/airflow/operators/python.py", line 175, in execute
    return_value = self.execute_callable()
  File "/home/airflow/.local/lib/python3.7/site-packages/airflow/operators/python.py", line 193, in execute_callable
    return self.python_callable(*self.op_args, **self.op_kwargs)
  File "/opt/airflow/dags/real_estate_dag.py", line 26, in read_csv
    df = pd.read_csv('sales.csv')
  File "/home/airflow/.local/lib/python3.7/site-packages/pandas/util/_decorators.py", line 311, in wrapper
    return func(*args, **kwargs)
  File "/home/airflow/.local/lib/python3.7/site-packages/pandas/io/parsers/readers.py", line 586, in read_csv
    return _read(filepath_or_buffer, kwds)
  File "/home/airflow/.local/lib/python3.7/site-packages/pandas/io/parsers/readers.py", line 482, in _read
    parser = TextFileReader(filepath_or_buffer, **kwds)
  File "/home/airflow/.local/lib/python3.7/site-packages/pandas/io/parsers/readers.py", line 811, in __init__
    self._engine = self._make_engine(self.engine)
  File "/home/airflow/.local/lib/python3.7/site-packages/pandas/io/parsers/readers.py", line 1040, in _make_engine
    return mapping[engine](self.f, **self.options)  # type: ignore[call-arg]
  File "/home/airflow/.local/lib/python3.7/site-packages/pandas/io/parsers/c_parser_wrapper.py", line 51, in __init__
    self._open_handles(src, kwds)
  File "/home/airflow/.local/lib/python3.7/site-packages/pandas/io/parsers/base_parser.py", line 229, in _open_handles
    errors=kwds.get("encoding_errors", "strict"),
  File "/home/airflow/.local/lib/python3.7/site-packages/pandas/io/common.py", line 707, in get_handle
    newline="",
FileNotFoundError: [Errno 2] No such file or directory: 'sales.csv'
[2023-01-21T04:11:30.083+0000] {taskinstance.py:1406} INFO - Marking task as FAILED. dag_id=real_estate_data_pipeline, task_id=read_csv, execution_date=20220110T110000, start_date=20230121T041128, end_date=20230121T041130
[2023-01-21T04:11:30.101+0000] {standard_task_runner.py:107} ERROR - Failed to execute job 488 for task read_csv ([Errno 2] No such file or directory: 'sales.csv'; 5442)
[2023-01-21T04:11:30.190+0000] {local_task_job.py:164} INFO - Task exited with return code 1
[2023-01-21T04:11:30.235+0000] {local_task_job.py:273} INFO - 0 downstream tasks scheduled from follow-on schedule check
